2024-11-19 21:26:53,339 ERROR: Registration error: 'username' [in /Users/yashvardhansharma/Downloads/webapp162/backend/core/blueprints/bp_auth.py:100]
Traceback (most recent call last):
  File "/Users/yashvardhansharma/Downloads/webapp162/backend/core/blueprints/bp_auth.py", line 56, in register
    (Users.username == data['username']) |
                      ~~~~^^^^^^^^^^^^
KeyError: 'username'
2024-11-19 21:26:53,409 ERROR: Registration error: 'username' [in /Users/yashvardhansharma/Downloads/webapp162/backend/core/blueprints/bp_auth.py:100]
Traceback (most recent call last):
  File "/Users/yashvardhansharma/Downloads/webapp162/backend/core/blueprints/bp_auth.py", line 56, in register
    (Users.username == data['username']) |
                      ~~~~^^^^^^^^^^^^
KeyError: 'username'
2024-11-19 21:26:54,345 ERROR: Registration error: 'username' [in /Users/yashvardhansharma/Downloads/webapp162/backend/core/blueprints/bp_auth.py:100]
Traceback (most recent call last):
  File "/Users/yashvardhansharma/Downloads/webapp162/backend/core/blueprints/bp_auth.py", line 56, in register
    (Users.username == data['username']) |
                      ~~~~^^^^^^^^^^^^
KeyError: 'username'
2024-11-19 21:27:57,065 INFO: Todo application startup [in /Users/yashvardhansharma/Downloads/webapp162/backend/run.py:115]
2024-11-19 21:27:57,239 INFO: Todo application startup [in /Users/yashvardhansharma/Downloads/webapp162/backend/run.py:115]
2024-11-19 21:28:40,000 ERROR: Registration error: 'username' [in /Users/yashvardhansharma/Downloads/webapp162/backend/core/blueprints/bp_auth.py:105]
Traceback (most recent call last):
  File "/Users/yashvardhansharma/Downloads/webapp162/backend/core/blueprints/bp_auth.py", line 62, in register
    (Users.username == data['username']) |
                      ~~~~^^^^^^^^^^^^
KeyError: 'username'
2024-11-19 21:29:15,549 INFO: Todo application startup [in /Users/yashvardhansharma/Downloads/webapp162/backend/run.py:115]
2024-11-19 21:29:38,819 INFO: Todo application startup [in /Users/yashvardhansharma/Downloads/webapp162/backend/run.py:115]
2024-11-19 21:29:38,987 INFO: Todo application startup [in /Users/yashvardhansharma/Downloads/webapp162/backend/run.py:115]
2024-11-19 21:30:08,307 ERROR: Registration error: 'username' [in /Users/yashvardhansharma/Downloads/webapp162/backend/core/blueprints/bp_auth.py:114]
Traceback (most recent call last):
  File "/Users/yashvardhansharma/Downloads/webapp162/backend/core/blueprints/bp_auth.py", line 71, in register
    (Users.username == data['username']) |
                      ~~~~^^^^^^^^^^^^
KeyError: 'username'
2024-11-19 21:30:09,266 ERROR: Registration error: 'username' [in /Users/yashvardhansharma/Downloads/webapp162/backend/core/blueprints/bp_auth.py:114]
Traceback (most recent call last):
  File "/Users/yashvardhansharma/Downloads/webapp162/backend/core/blueprints/bp_auth.py", line 71, in register
    (Users.username == data['username']) |
                      ~~~~^^^^^^^^^^^^
KeyError: 'username'
2024-11-19 21:30:51,214 INFO: Todo application startup [in /Users/yashvardhansharma/Downloads/webapp162/backend/run.py:115]
2024-11-20 00:29:10,995 INFO: Todo application startup [in /Users/yashvardhansharma/Downloads/webapp162/backend/run.py:86]
2024-11-20 00:29:11,016 INFO: Database tables created successfully [in /Users/yashvardhansharma/Downloads/webapp162/backend/run.py:103]
2024-11-20 00:29:11,153 INFO: Todo application startup [in /Users/yashvardhansharma/Downloads/webapp162/backend/run.py:86]
2024-11-20 00:29:11,166 INFO: Database tables created successfully [in /Users/yashvardhansharma/Downloads/webapp162/backend/run.py:103]
2024-11-20 00:34:00,568 INFO: Todo application startup [in /Users/yashvardhansharma/Downloads/webapp162/backend/run.py:86]
2024-11-20 00:34:00,588 INFO: Database tables created successfully [in /Users/yashvardhansharma/Downloads/webapp162/backend/run.py:103]
2024-11-20 00:34:00,747 INFO: Todo application startup [in /Users/yashvardhansharma/Downloads/webapp162/backend/run.py:86]
2024-11-20 00:34:00,761 INFO: Database tables created successfully [in /Users/yashvardhansharma/Downloads/webapp162/backend/run.py:103]
2024-11-20 01:51:04,710 ERROR: Registration error: Tasks.subtasks and back-reference Tasks.parent are both of the same direction symbol('ONETOMANY').  Did you mean to set remote_side on the many-to-one side ? [in /Users/yashvardhansharma/Downloads/webapp162/backend/core/blueprints/bp_auth.py:108]
Traceback (most recent call last):
  File "/Users/yashvardhansharma/Downloads/webapp162/backend/core/blueprints/bp_auth.py", line 85, in register
    new_user = Users(
               ^^^^^^
  File "<string>", line 4, in __init__
  File "/Users/yashvardhansharma/Downloads/webapp162/venv/lib/python3.12/site-packages/sqlalchemy/orm/state.py", line 476, in _initialize_instance
    manager.dispatch.init(self, args, kwargs)
  File "/Users/yashvardhansharma/Downloads/webapp162/venv/lib/python3.12/site-packages/sqlalchemy/event/attr.py", line 346, in __call__
    fn(*args, **kw)
  File "/Users/yashvardhansharma/Downloads/webapp162/venv/lib/python3.12/site-packages/sqlalchemy/orm/mapper.py", line 3716, in _event_on_init
    instrumenting_mapper._check_configure()
  File "/Users/yashvardhansharma/Downloads/webapp162/venv/lib/python3.12/site-packages/sqlalchemy/orm/mapper.py", line 1941, in _check_configure
    _configure_registries({self.registry}, cascade=True)
  File "/Users/yashvardhansharma/Downloads/webapp162/venv/lib/python3.12/site-packages/sqlalchemy/orm/mapper.py", line 3527, in _configure_registries
    _do_configure_registries(registries, cascade)
  File "/Users/yashvardhansharma/Downloads/webapp162/venv/lib/python3.12/site-packages/sqlalchemy/orm/mapper.py", line 3566, in _do_configure_registries
    mapper._post_configure_properties()
  File "/Users/yashvardhansharma/Downloads/webapp162/venv/lib/python3.12/site-packages/sqlalchemy/orm/mapper.py", line 1958, in _post_configure_properties
    prop.init()
  File "/Users/yashvardhansharma/Downloads/webapp162/venv/lib/python3.12/site-packages/sqlalchemy/orm/interfaces.py", line 231, in init
    self.do_init()
  File "/Users/yashvardhansharma/Downloads/webapp162/venv/lib/python3.12/site-packages/sqlalchemy/orm/relationships.py", line 2155, in do_init
    self._generate_backref()
  File "/Users/yashvardhansharma/Downloads/webapp162/venv/lib/python3.12/site-packages/sqlalchemy/orm/relationships.py", line 2488, in _generate_backref
    mapper._configure_property(backref_key, relationship)
  File "/Users/yashvardhansharma/Downloads/webapp162/venv/lib/python3.12/site-packages/sqlalchemy/orm/mapper.py", line 1850, in _configure_property
    prop.init()
  File "/Users/yashvardhansharma/Downloads/webapp162/venv/lib/python3.12/site-packages/sqlalchemy/orm/interfaces.py", line 231, in init
    self.do_init()
  File "/Users/yashvardhansharma/Downloads/webapp162/venv/lib/python3.12/site-packages/sqlalchemy/orm/relationships.py", line 2155, in do_init
    self._generate_backref()
  File "/Users/yashvardhansharma/Downloads/webapp162/venv/lib/python3.12/site-packages/sqlalchemy/orm/relationships.py", line 2491, in _generate_backref
    self._add_reverse_property(self.back_populates)
  File "/Users/yashvardhansharma/Downloads/webapp162/venv/lib/python3.12/site-packages/sqlalchemy/orm/relationships.py", line 2094, in _add_reverse_property
    raise sa_exc.ArgumentError(
sqlalchemy.exc.ArgumentError: Tasks.subtasks and back-reference Tasks.parent are both of the same direction symbol('ONETOMANY').  Did you mean to set remote_side on the many-to-one side ?
2024-11-20 01:51:41,505 ERROR: Registration error: One or more mappers failed to initialize - can't proceed with initialization of other mappers. Triggering mapper: 'mapped class Tasks->tasks'. Original exception was: Tasks.subtasks and back-reference Tasks.parent are both of the same direction symbol('ONETOMANY').  Did you mean to set remote_side on the many-to-one side ? [in /Users/yashvardhansharma/Downloads/webapp162/backend/core/blueprints/bp_auth.py:108]
Traceback (most recent call last):
  File "/Users/yashvardhansharma/Downloads/webapp162/backend/core/blueprints/bp_auth.py", line 85, in register
    new_user = Users(
               ^^^^^^
  File "<string>", line 4, in __init__
  File "/Users/yashvardhansharma/Downloads/webapp162/venv/lib/python3.12/site-packages/sqlalchemy/orm/state.py", line 476, in _initialize_instance
    manager.dispatch.init(self, args, kwargs)
  File "/Users/yashvardhansharma/Downloads/webapp162/venv/lib/python3.12/site-packages/sqlalchemy/event/attr.py", line 346, in __call__
    fn(*args, **kw)
  File "/Users/yashvardhansharma/Downloads/webapp162/venv/lib/python3.12/site-packages/sqlalchemy/orm/mapper.py", line 3716, in _event_on_init
    instrumenting_mapper._check_configure()
  File "/Users/yashvardhansharma/Downloads/webapp162/venv/lib/python3.12/site-packages/sqlalchemy/orm/mapper.py", line 1941, in _check_configure
    _configure_registries({self.registry}, cascade=True)
  File "/Users/yashvardhansharma/Downloads/webapp162/venv/lib/python3.12/site-packages/sqlalchemy/orm/mapper.py", line 3527, in _configure_registries
    _do_configure_registries(registries, cascade)
  File "/Users/yashvardhansharma/Downloads/webapp162/venv/lib/python3.12/site-packages/sqlalchemy/orm/mapper.py", line 3562, in _do_configure_registries
    raise e
sqlalchemy.exc.InvalidRequestError: One or more mappers failed to initialize - can't proceed with initialization of other mappers. Triggering mapper: 'mapped class Tasks->tasks'. Original exception was: Tasks.subtasks and back-reference Tasks.parent are both of the same direction symbol('ONETOMANY').  Did you mean to set remote_side on the many-to-one side ?
2024-11-20 01:55:50,764 INFO: Todo application startup [in /Users/yashvardhansharma/Downloads/webapp162/backend/run.py:84]
2024-11-20 01:55:50,987 INFO: Todo application startup [in /Users/yashvardhansharma/Downloads/webapp162/backend/run.py:84]
