2024-11-19 21:21:02,843 ERROR: Login error: (sqlite3.OperationalError) unable to open database file
(Background on this error at: https://sqlalche.me/e/20/e3q8) [in /Users/yashvardhansharma/Downloads/webapp162/backend/core/blueprints/bp_auth.py:134]
Traceback (most recent call last):
  File "/Users/yashvardhansharma/Downloads/webapp162/venv/lib/python3.12/site-packages/sqlalchemy/engine/base.py", line 145, in __init__
    self._dbapi_connection = engine.raw_connection()
                             ^^^^^^^^^^^^^^^^^^^^^^^
  File "/Users/yashvardhansharma/Downloads/webapp162/venv/lib/python3.12/site-packages/sqlalchemy/engine/base.py", line 3292, in raw_connection
    return self.pool.connect()
           ^^^^^^^^^^^^^^^^^^^
  File "/Users/yashvardhansharma/Downloads/webapp162/venv/lib/python3.12/site-packages/sqlalchemy/pool/base.py", line 452, in connect
    return _ConnectionFairy._checkout(self)
           ^^^^^^^^^^^^^^^^^^^^^^^^^^^^^^^^
  File "/Users/yashvardhansharma/Downloads/webapp162/venv/lib/python3.12/site-packages/sqlalchemy/pool/base.py", line 1269, in _checkout
    fairy = _ConnectionRecord.checkout(pool)
            ^^^^^^^^^^^^^^^^^^^^^^^^^^^^^^^^
  File "/Users/yashvardhansharma/Downloads/webapp162/venv/lib/python3.12/site-packages/sqlalchemy/pool/base.py", line 716, in checkout
    rec = pool._do_get()
          ^^^^^^^^^^^^^^
  File "/Users/yashvardhansharma/Downloads/webapp162/venv/lib/python3.12/site-packages/sqlalchemy/pool/impl.py", line 169, in _do_get
    with util.safe_reraise():
  File "/Users/yashvardhansharma/Downloads/webapp162/venv/lib/python3.12/site-packages/sqlalchemy/util/langhelpers.py", line 146, in __exit__
    raise exc_value.with_traceback(exc_tb)
  File "/Users/yashvardhansharma/Downloads/webapp162/venv/lib/python3.12/site-packages/sqlalchemy/pool/impl.py", line 167, in _do_get
    return self._create_connection()
           ^^^^^^^^^^^^^^^^^^^^^^^^^
  File "/Users/yashvardhansharma/Downloads/webapp162/venv/lib/python3.12/site-packages/sqlalchemy/pool/base.py", line 393, in _create_connection
    return _ConnectionRecord(self)
           ^^^^^^^^^^^^^^^^^^^^^^^
  File "/Users/yashvardhansharma/Downloads/webapp162/venv/lib/python3.12/site-packages/sqlalchemy/pool/base.py", line 678, in __init__
    self.__connect()
  File "/Users/yashvardhansharma/Downloads/webapp162/venv/lib/python3.12/site-packages/sqlalchemy/pool/base.py", line 902, in __connect
    with util.safe_reraise():
  File "/Users/yashvardhansharma/Downloads/webapp162/venv/lib/python3.12/site-packages/sqlalchemy/util/langhelpers.py", line 146, in __exit__
    raise exc_value.with_traceback(exc_tb)
  File "/Users/yashvardhansharma/Downloads/webapp162/venv/lib/python3.12/site-packages/sqlalchemy/pool/base.py", line 898, in __connect
    self.dbapi_connection = connection = pool._invoke_creator(self)
                                         ^^^^^^^^^^^^^^^^^^^^^^^^^^
  File "/Users/yashvardhansharma/Downloads/webapp162/venv/lib/python3.12/site-packages/sqlalchemy/engine/create.py", line 637, in connect
    return dialect.connect(*cargs, **cparams)
           ^^^^^^^^^^^^^^^^^^^^^^^^^^^^^^^^^^
  File "/Users/yashvardhansharma/Downloads/webapp162/venv/lib/python3.12/site-packages/sqlalchemy/engine/default.py", line 616, in connect
    return self.loaded_dbapi.connect(*cargs, **cparams)
           ^^^^^^^^^^^^^^^^^^^^^^^^^^^^^^^^^^^^^^^^^^^^
sqlite3.OperationalError: unable to open database file

The above exception was the direct cause of the following exception:

Traceback (most recent call last):
  File "/Users/yashvardhansharma/Downloads/webapp162/backend/core/blueprints/bp_auth.py", line 100, in login
    ).first()
      ^^^^^^^
  File "/Users/yashvardhansharma/Downloads/webapp162/venv/lib/python3.12/site-packages/sqlalchemy/orm/query.py", line 2748, in first
    return self.limit(1)._iter().first()  # type: ignore
           ^^^^^^^^^^^^^^^^^^^^^
  File "/Users/yashvardhansharma/Downloads/webapp162/venv/lib/python3.12/site-packages/sqlalchemy/orm/query.py", line 2847, in _iter
    result: Union[ScalarResult[_T], Result[_T]] = self.session.execute(
                                                  ^^^^^^^^^^^^^^^^^^^^^
  File "/Users/yashvardhansharma/Downloads/webapp162/venv/lib/python3.12/site-packages/sqlalchemy/orm/session.py", line 2306, in execute
    return self._execute_internal(
           ^^^^^^^^^^^^^^^^^^^^^^^
  File "/Users/yashvardhansharma/Downloads/webapp162/venv/lib/python3.12/site-packages/sqlalchemy/orm/session.py", line 2178, in _execute_internal
    conn = self._connection_for_bind(bind)
           ^^^^^^^^^^^^^^^^^^^^^^^^^^^^^^^
  File "/Users/yashvardhansharma/Downloads/webapp162/venv/lib/python3.12/site-packages/sqlalchemy/orm/session.py", line 2045, in _connection_for_bind
    return trans._connection_for_bind(engine, execution_options)
           ^^^^^^^^^^^^^^^^^^^^^^^^^^^^^^^^^^^^^^^^^^^^^^^^^^^^^
  File "<string>", line 2, in _connection_for_bind
  File "/Users/yashvardhansharma/Downloads/webapp162/venv/lib/python3.12/site-packages/sqlalchemy/orm/state_changes.py", line 139, in _go
    ret_value = fn(self, *arg, **kw)
                ^^^^^^^^^^^^^^^^^^^^
  File "/Users/yashvardhansharma/Downloads/webapp162/venv/lib/python3.12/site-packages/sqlalchemy/orm/session.py", line 1143, in _connection_for_bind
    conn = bind.connect()
           ^^^^^^^^^^^^^^
  File "/Users/yashvardhansharma/Downloads/webapp162/venv/lib/python3.12/site-packages/sqlalchemy/engine/base.py", line 3268, in connect
    return self._connection_cls(self)
           ^^^^^^^^^^^^^^^^^^^^^^^^^^
  File "/Users/yashvardhansharma/Downloads/webapp162/venv/lib/python3.12/site-packages/sqlalchemy/engine/base.py", line 147, in __init__
    Connection._handle_dbapi_exception_noconnection(
  File "/Users/yashvardhansharma/Downloads/webapp162/venv/lib/python3.12/site-packages/sqlalchemy/engine/base.py", line 2430, in _handle_dbapi_exception_noconnection
    raise sqlalchemy_exception.with_traceback(exc_info[2]) from e
  File "/Users/yashvardhansharma/Downloads/webapp162/venv/lib/python3.12/site-packages/sqlalchemy/engine/base.py", line 145, in __init__
    self._dbapi_connection = engine.raw_connection()
                             ^^^^^^^^^^^^^^^^^^^^^^^
  File "/Users/yashvardhansharma/Downloads/webapp162/venv/lib/python3.12/site-packages/sqlalchemy/engine/base.py", line 3292, in raw_connection
    return self.pool.connect()
           ^^^^^^^^^^^^^^^^^^^
  File "/Users/yashvardhansharma/Downloads/webapp162/venv/lib/python3.12/site-packages/sqlalchemy/pool/base.py", line 452, in connect
    return _ConnectionFairy._checkout(self)
           ^^^^^^^^^^^^^^^^^^^^^^^^^^^^^^^^
  File "/Users/yashvardhansharma/Downloads/webapp162/venv/lib/python3.12/site-packages/sqlalchemy/pool/base.py", line 1269, in _checkout
    fairy = _ConnectionRecord.checkout(pool)
            ^^^^^^^^^^^^^^^^^^^^^^^^^^^^^^^^
  File "/Users/yashvardhansharma/Downloads/webapp162/venv/lib/python3.12/site-packages/sqlalchemy/pool/base.py", line 716, in checkout
    rec = pool._do_get()
          ^^^^^^^^^^^^^^
  File "/Users/yashvardhansharma/Downloads/webapp162/venv/lib/python3.12/site-packages/sqlalchemy/pool/impl.py", line 169, in _do_get
    with util.safe_reraise():
  File "/Users/yashvardhansharma/Downloads/webapp162/venv/lib/python3.12/site-packages/sqlalchemy/util/langhelpers.py", line 146, in __exit__
    raise exc_value.with_traceback(exc_tb)
  File "/Users/yashvardhansharma/Downloads/webapp162/venv/lib/python3.12/site-packages/sqlalchemy/pool/impl.py", line 167, in _do_get
    return self._create_connection()
           ^^^^^^^^^^^^^^^^^^^^^^^^^
  File "/Users/yashvardhansharma/Downloads/webapp162/venv/lib/python3.12/site-packages/sqlalchemy/pool/base.py", line 393, in _create_connection
    return _ConnectionRecord(self)
           ^^^^^^^^^^^^^^^^^^^^^^^
  File "/Users/yashvardhansharma/Downloads/webapp162/venv/lib/python3.12/site-packages/sqlalchemy/pool/base.py", line 678, in __init__
    self.__connect()
  File "/Users/yashvardhansharma/Downloads/webapp162/venv/lib/python3.12/site-packages/sqlalchemy/pool/base.py", line 902, in __connect
    with util.safe_reraise():
  File "/Users/yashvardhansharma/Downloads/webapp162/venv/lib/python3.12/site-packages/sqlalchemy/util/langhelpers.py", line 146, in __exit__
    raise exc_value.with_traceback(exc_tb)
  File "/Users/yashvardhansharma/Downloads/webapp162/venv/lib/python3.12/site-packages/sqlalchemy/pool/base.py", line 898, in __connect
    self.dbapi_connection = connection = pool._invoke_creator(self)
                                         ^^^^^^^^^^^^^^^^^^^^^^^^^^
  File "/Users/yashvardhansharma/Downloads/webapp162/venv/lib/python3.12/site-packages/sqlalchemy/engine/create.py", line 637, in connect
    return dialect.connect(*cargs, **cparams)
           ^^^^^^^^^^^^^^^^^^^^^^^^^^^^^^^^^^
  File "/Users/yashvardhansharma/Downloads/webapp162/venv/lib/python3.12/site-packages/sqlalchemy/engine/default.py", line 616, in connect
    return self.loaded_dbapi.connect(*cargs, **cparams)
           ^^^^^^^^^^^^^^^^^^^^^^^^^^^^^^^^^^^^^^^^^^^^
sqlalchemy.exc.OperationalError: (sqlite3.OperationalError) unable to open database file
(Background on this error at: https://sqlalche.me/e/20/e3q8)
2024-11-19 21:24:18,099 INFO: Todo application startup [in /Users/yashvardhansharma/Downloads/webapp162/backend/run.py:106]
2024-11-19 21:24:18,274 INFO: Todo application startup [in /Users/yashvardhansharma/Downloads/webapp162/backend/run.py:106]
2024-11-19 21:26:29,245 INFO: Todo application startup [in /Users/yashvardhansharma/Downloads/webapp162/backend/run.py:115]
2024-11-19 21:26:37,718 INFO: Todo application startup [in /Users/yashvardhansharma/Downloads/webapp162/backend/run.py:115]
2024-11-19 21:26:50,138 INFO: Todo application startup [in /Users/yashvardhansharma/Downloads/webapp162/backend/run.py:115]
2024-11-19 21:26:50,304 INFO: Todo application startup [in /Users/yashvardhansharma/Downloads/webapp162/backend/run.py:115]
